Workbook

Sheet Dashboard
A1: COLD STORAGE PROJECT - DPR DASHBOARD
A4: Report Date: | B4: =TODAY() -> 46210
A6: Overall Project % | C6: Total Activities | E6: Rooms Ready for Handover | G6: Total Rooms Tracked
A7: =IFERROR(AVERAGE('Ambient Room'!J7:J21,'Chiller Room'!J7:J21,'Freezer Room'!J7:J21,'Blast Room'!J7:J21,'FNV Room'!J7:J21,'Corridor & Warm Room'!J7:J21,'Ante Room'!J7:J21,Common_Works!J5:J17),0) -> 0.88732394 | C7: =COUNTA('Ambient Room'!C7:C21)+COUNTA('Chiller Room'!C7:C21)+COUNTA('Freezer Room'!C7:C21)+COUNTA('Blast Room'!C7:C21)+COUNTA('FNV Room'!C7:C21)+COUNTA('Corridor & Warm Room'!C7:C21)+COUNTA('Ante Room'!C7:C21)+COUNTA(Common_Works!C5:C17) -> 118 | E7: =COUNTIF(Room_Handover!I5:I11,"Ready for Handover") -> 0 | G7: =7 -> 7
A10: ROOM-WISE HANDOVER STATUS
A11: Room | B11: PUF % | C11: Door % | D11: Floor % | E11: Overall % | G11: Planned Handover | H11: Status
A12: =Room_Handover!A5 -> Ambient | B12: =Room_Handover!B5 -> 0.88732394 | C12: =Room_Handover!C5 -> 0 | D12: =Room_Handover!D5 -> 0 | E12: =Room_Handover!E5 -> 0.29577465 | G12: =Room_Handover!F5 -> 46213 | H12: =Room_Handover!I5 -> In Progress
A13: =Room_Handover!A6 -> Chiller | B13: =Room_Handover!B6 -> 0 | C13: =Room_Handover!C6 -> 0 | D13: =Room_Handover!D6 -> 0 | E13: =Room_Handover!E6 -> 0 | G13: =Room_Handover!F6 | H13: =Room_Handover!I6 -> Not Started
A14: =Room_Handover!A7 -> Freezer | B14: =Room_Handover!B7 -> 0 | C14: =Room_Handover!C7 -> 0 | D14: =Room_Handover!D7 -> 0 | E14: =Room_Handover!E7 -> 0 | G14: =Room_Handover!F7 | H14: =Room_Handover!I7 -> Not Started
A15: =Room_Handover!A8 -> Blast | B15: =Room_Handover!B8 -> 0 | C15: =Room_Handover!C8 -> 0 | D15: =Room_Handover!D8 -> 0 | E15: =Room_Handover!E8 -> 0 | G15: =Room_Handover!F8 | H15: =Room_Handover!I8 -> Not Started
A16: =Room_Handover!A9 -> FNV | B16: =Room_Handover!B9 -> 0 | C16: =Room_Handover!C9 -> 0 | D16: =Room_Handover!D9 -> 0 | E16: =Room_Handover!E9 -> 0 | G16: =Room_Handover!F9 | H16: =Room_Handover!I9 -> Not Started
A17: =Room_Handover!A10 -> Corridor & Warm Room | B17: =Room_Handover!B10 -> 0 | C17: =Room_Handover!C10 -> 0 | D17: =Room_Handover!D10 -> 0 | E17: =Room_Handover!E10 -> 0 | G17: =Room_Handover!F10 | H17: =Room_Handover!I10 -> Not Started
A18: =Room_Handover!A11 -> Ante Room | B18: =Room_Handover!B11 -> 0 | C18: =Room_Handover!C11 -> 0 | D18: =Room_Handover!D11 -> 0 | E18: =Room_Handover!E11 -> 0 | G18: =Room_Handover!F11 | H18: =Room_Handover!I11 -> Not Started
A21: PLANT-WIDE WORK (Refrigeration / Electrical)
A22: Category | B22: % Complete
A23: Refrigeration | B23: =Room_Handover!B16 -> 0
A24: Electrical | B24: =Room_Handover!B17 -> 0

Sheet Daily_Entry
A1: DAILY PROGRESS ENTRY (fill this every day - one row per activity)
A3: Instructions: Add a new row for every activity completed today. Select Room, Category & Item from the dropdown; enter today's quantity only (not cumulative). Every room sheet updates automatically.
A4: Date | B4: Room | C4: Category | D4: Item / Activity | E4: UOM | F4: Qty Done Today | G4: Labour / Team | H4: Remarks
A5: 46184 | B5: Ambient | C5: PUF Panel | D5: Front Wall | E5: Sq.m | F5: 90 | G5: Team A | H5: Initial fixing started
A6: 46185 | B6: Ambient | C6: PUF Panel | D6: Front Wall | E6: Sq.m | F6: 75 | G6: Team A
A7: 46186 | B7: Chiller | C7: PUF Panel | D7: Front Wall | E7: Sq.m | F7: 36 | G7: Team A | H7: 201 sq.m done till date, 12 pending
A8: 46210 | B8: Ambient | C8: PUF Panel | D8: Back Wall | E8: sq.m | F8: 55 | G8: farr
A9: 46187 | B9: Freezer | C9: Refrigeration | D9: Refrigeration Piping | E9: Sq.m | F9: 10 | G9: Rehman

Sheet Ambient Room
A1: AMBIENT ROOM - SCOPE & PROGRESS TRACKER
A4: Room Overall % Complete: | D4: =IFERROR(AVERAGE(J7:J21),0) -> 0.88732394 | E4: Planned Handover Date: | G4: =IF(COUNT(H7:H21)=0,"",MIN(H7:H21)) -> 46213 | H4: Status: | I4: =IF(D4=1,"Ready for Handover",IF(D4>=0.75,"Near Completion",IF(D4>0,"In Progress","Not Started"))) -> Near Completion
A6: S.No | B6: Category | C6: Item / Activity | D6: UOM | E6: Target Qty | F6: Planned Start | G6: Planned Finish | H6: Planned Handover | I6: Cumulative Qty Done | J6: % Complete | K6: Balance Qty | L6: Last Updated | M6: Status | N6: Remarks
A7: 1 | B7: PUF Panel | C7: Front Wall | D7: Sq.m | E7: 213 | F7: 46199 | G7: 46211 | H7: 46213 | I7: =SUMIFS(Daily_Entry!$F$5:$F$1000,Daily_Entry!$B$5:$B$1000,"Ambient",Daily_Entry!$D$5:$D$1000,C7) -> 165 | J7: =IF(OR(E7="",E7=0),"",I7/E7) -> 0.77464789 | K7: =IF(E7="","",E7-I7) -> 48 | L7: =IF(MAXIFS(Daily_Entry!$A$5:$A$1000,Daily_Entry!$B$5:$B$1000,"Ambient",Daily_Entry!$D$5:$D$1000,C7)=0,"",MAXIFS(Daily_Entry!$A$5:$A$1000,Daily_Entry!$B$5:$B$1000,"Ambient",Daily_Entry!$D$5:$D$1000,C7)) -> 46185 | M7: =IF(I7=0,"Not Started",IF(AND(E7<>"",I7>=E7),"Completed","In Progress")) -> In Progress
A8: 2 | B8: PUF Panel | C8: Back Wall | D8: Sq.m | E8: 200 | I8: 200 | J8: =IF(OR(E8="",E8=0),"",I8/E8) -> 1 | K8: =IF(E8="","",E8-I8) -> 0 | L8: =IF(MAXIFS(Daily_Entry!$A$5:$A$1000,Daily_Entry!$B$5:$B$1000,"Ambient",Daily_Entry!$D$5:$D$1000,C8)=0,"",MAXIFS(Daily_Entry!$A$5:$A$1000,Daily_Entry!$B$5:$B$1000,"Ambient",Daily_Entry!$D$5:$D$1000,C8)) -> 46210 | M8: =IF(I8=0,"Not Started",IF(AND(E8<>"",I8>=E8),"Completed","In Progress")) -> Completed
A9: 3 | B9: PUF Panel | C9: Left Side Wall | D9: Sq.m | I9: =SUMIFS(Daily_Entry!$F$5:$F$1000,Daily_Entry!$B$5:$B$1000,"Ambient",Daily_Entry!$D$5:$D$1000,C9) -> 0 | J9: =IF(OR(E9="",E9=0),"",I9/E9) | K9: =IF(E9="","",E9-I9) | L9: =IF(MAXIFS(Daily_Entry!$A$5:$A$1000,Daily_Entry!$B$5:$B$1000,"Ambient",Daily_Entry!$D$5:$D$1000,C9)=0,"",MAXIFS(Daily_Entry!$A$5:$A$1000,Daily_Entry!$B$5:$B$1000,"Ambient",Daily_Entry!$D$5:$D$1000,C9)) | M9: =IF(I9=0,"Not Started",IF(AND(E9<>"",I9>=E9),"Completed","In Progress")) -> Not Started
A10: 4 | B10: PUF Panel | C10: Right Side Wall | D10: Sq.m | I10: =SUMIFS(Daily_Entry!$F$5:$F$1000,Daily_Entry!$B$5:$B$1000,"Ambient",Daily_Entry!$D$5:$D$1000,C10) -> 0 | J10: =IF(OR(E10="",E10=0),"",I10/E10) | K10: =IF(E10="","",E10-I10) | L10: =IF(MAXIFS(Daily_Entry!$A$5:$A$1000,Daily_Entry!$B$5:$B$1000,"Ambient",Daily_Entry!$D$5:$D$1000,C10)=0,"",MAXIFS(Daily_Entry!$A$5:$A$1000,Daily_Entry!$B$5:$B$1000,"Ambient",Daily_Entry!$D$5:$D$1000,C10)) | M10: =IF(I10=0,"Not Started",IF(AND(E10<>"",I10>=E10),"Completed","In Progress")) -> Not Started
A11: 5 | B11: PUF Panel | C11: Top Ceiling | D11: Sq.m | I11: =SUMIFS(Daily_Entry!$F$5:$F$1000,Daily_Entry!$B$5:$B$1000,"Ambient",Daily_Entry!$D$5:$D$1000,C11) -> 0 | J11: =IF(OR(E11="",E11=0),"",I11/E11) | K11: =IF(E11="","",E11-I11) | L11: =IF(MAXIFS(Daily_Entry!$A$5:$A$1000,Daily_Entry!$B$5:$B$1000,"Ambient",Daily_Entry!$D$5:$D$1000,C11)=0,"",MAXIFS(Daily_Entry!$A$5:$A$1000,Daily_Entry!$B$5:$B$1000,"Ambient",Daily_Entry!$D$5:$D$1000,C11)) | M11: =IF(I11=0,"Not Started",IF(AND(E11<>"",I11>=E11),"Completed","In Progress")) -> Not Started
A12: 6 | B12: PUF Panel | C12: PUF Slab (Floor) | D12: Sq.m | I12: =SUMIFS(Daily_Entry!$F$5:$F$1000,Daily_Entry!$B$5:$B$1000,"Ambient",Daily_Entry!$D$5:$D$1000,C12) -> 0 | J12: =IF(OR(E12="",E12=0),"",I12/E12) | K12: =IF(E12="","",E12-I12) | L12: =IF(MAXIFS(Daily_Entry!$A$5:$A$1000,Daily_Entry!$B$5:$B$1000,"Ambient",Daily_Entry!$D$5:$D$1000,C12)=0,"",MAXIFS(Daily_Entry!$A$5:$A$1000,Daily_Entry!$B$5:$B$1000,"Ambient",Daily_Entry!$D$5:$D$1000,C12)) | M12: =IF(I12=0,"Not Started",IF(AND(E12<>"",I12>=E12),"Completed","In Progress")) -> Not Started
A13: 7 | B13: PUF Panel | C13: Door Cutting | D13: Nos | I13: =SUMIFS(Daily_Entry!$F$5:$F$1000,Daily_Entry!$B$5:$B$1000,"Ambient",Daily_Entry!$D$5:$D$1000,C13) -> 0 | J13: =IF(OR(E13="",E13=0),"",I13/E13) | K13: =IF(E13="","",E13-I13) | L13: =IF(MAXIFS(Daily_Entry!$A$5:$A$1000,Daily_Entry!$B$5:$B$1000,"Ambient",Daily_Entry!$D$5:$D$1000,C13)=0,"",MAXIFS(Daily_Entry!$A$5:$A$1000,Daily_Entry!$B$5:$B$1000,"Ambient",Daily_Entry!$D$5:$D$1000,C13)) | M13: =IF(I13=0,"Not Started",IF(AND(E13<>"",I13>=E13),"Completed","In Progress")) -> Not Started
A14: 8 | B14: PUF Panel | C14: Silicon Filling - Inside | D14: Rmt | I14: =SUMIFS(Daily_Entry!$F$5:$F$1000,Daily_Entry!$B$5:$B$1000,"Ambient",Daily_Entry!$D$5:$D$1000,C14) -> 0 | J14: =IF(OR(E14="",E14=0),"",I14/E14) | K14: =IF(E14="","",E14-I14) | L14: =IF(MAXIFS(Daily_Entry!$A$5:$A$1000,Daily_Entry!$B$5:$B$1000,"Ambient",Daily_Entry!$D$5:$D$1000,C14)=0,"",MAXIFS(Daily_Entry!$A$5:$A$1000,Daily_Entry!$B$5:$B$1000,"Ambient",Daily_Entry!$D$5:$D$1000,C14)) | M14: =IF(I14=0,"Not Started",IF(AND(E14<>"",I14>=E14),"Completed","In Progress")) -> Not Started
A15: 9 | B15: PUF Panel | C15: Silicon Filling - Outside | D15: Rmt | I15: =SUMIFS(Daily_Entry!$F$5:$F$1000,Daily_Entry!$B$5:$B$1000,"Ambient",Daily_Entry!$D$5:$D$1000,C15) -> 0 | J15: =IF(OR(E15="",E15=0),"",I15/E15) | K15: =IF(E15="","",E15-I15) | L15: =IF(MAXIFS(Daily_Entry!$A$5:$A$1000,Daily_Entry!$B$5:$B$1000,"Ambient",Daily_Entry!$D$5:$D$1000,C15)=0,"",MAXIFS(Daily_Entry!$A$5:$A$1000,Daily_Entry!$B$5:$B$1000,"Ambient",Daily_Entry!$D$5:$D$1000,C15)) | M15: =IF(I15=0,"Not Started",IF(AND(E15<>"",I15>=E15),"Completed","In Progress")) -> Not Started
A16: 10 | B16: Door Work | C16: Door Installation | D16: Nos | I16: =SUMIFS(Daily_Entry!$F$5:$F$1000,Daily_Entry!$B$5:$B$1000,"Ambient",Daily_Entry!$D$5:$D$1000,C16) -> 0 | J16: =IF(OR(E16="",E16=0),"",I16/E16) | K16: =IF(E16="","",E16-I16) | L16: =IF(MAXIFS(Daily_Entry!$A$5:$A$1000,Daily_Entry!$B$5:$B$1000,"Ambient",Daily_Entry!$D$5:$D$1000,C16)=0,"",MAXIFS(Daily_Entry!$A$5:$A$1000,Daily_Entry!$B$5:$B$1000,"Ambient",Daily_Entry!$D$5:$D$1000,C16)) | M16: =IF(I16=0,"Not Started",IF(AND(E16<>"",I16>=E16),"Completed","In Progress")) -> Not Started
A17: 11 | B17: Door Work | C17: Falcon Sensor Installation | D17: Nos | I17: =SUMIFS(Daily_Entry!$F$5:$F$1000,Daily_Entry!$B$5:$B$1000,"Ambient",Daily_Entry!$D$5:$D$1000,C17) -> 0 | J17: =IF(OR(E17="",E17=0),"",I17/E17) | K17: =IF(E17="","",E17-I17) | L17: =IF(MAXIFS(Daily_Entry!$A$5:$A$1000,Daily_Entry!$B$5:$B$1000,"Ambient",Daily_Entry!$D$5:$D$1000,C17)=0,"",MAXIFS(Daily_Entry!$A$5:$A$1000,Daily_Entry!$B$5:$B$1000,"Ambient",Daily_Entry!$D$5:$D$1000,C17)) | M17: =IF(I17=0,"Not Started",IF(AND(E17<>"",I17>=E17),"Completed","In Progress")) -> Not Started
A18: 12 | B18: Door Work | C18: Air Curtain Installation | D18: Nos | I18: =SUMIFS(Daily_Entry!$F$5:$F$1000,Daily_Entry!$B$5:$B$1000,"Ambient",Daily_Entry!$D$5:$D$1000,C18) -> 0 | J18: =IF(OR(E18="",E18=0),"",I18/E18) | K18: =IF(E18="","",E18-I18) | L18: =IF(MAXIFS(Daily_Entry!$A$5:$A$1000,Daily_Entry!$B$5:$B$1000,"Ambient",Daily_Entry!$D$5:$D$1000,C18)=0,"",MAXIFS(Daily_Entry!$A$5:$A$1000,Daily_Entry!$B$5:$B$1000,"Ambient",Daily_Entry!$D$5:$D$1000,C18)) | M18: =IF(I18=0,"Not Started",IF(AND(E18<>"",I18>=E18),"Completed","In Progress")) -> Not Started
A19: 13 | B19: Door Work | C19: PVC Curtain Installation | D19: Nos | I19: =SUMIFS(Daily_Entry!$F$5:$F$1000,Daily_Entry!$B$5:$B$1000,"Ambient",Daily_Entry!$D$5:$D$1000,C19) -> 0 | J19: =IF(OR(E19="",E19=0),"",I19/E19) | K19: =IF(E19="","",E19-I19) | L19: =IF(MAXIFS(Daily_Entry!$A$5:$A$1000,Daily_Entry!$B$5:$B$1000,"Ambient",Daily_Entry!$D$5:$D$1000,C19)=0,"",MAXIFS(Daily_Entry!$A$5:$A$1000,Daily_Entry!$B$5:$B$1000,"Ambient",Daily_Entry!$D$5:$D$1000,C19)) | M19: =IF(I19=0,"Not Started",IF(AND(E19<>"",I19>=E19),"Completed","In Progress")) -> Not Started
A20: 14 | B20: Door Work | C20: Door Alarm & Hooter Installation | D20: Nos | I20: =SUMIFS(Daily_Entry!$F$5:$F$1000,Daily_Entry!$B$5:$B$1000,"Ambient",Daily_Entry!$D$5:$D$1000,C20) -> 0 | J20: =IF(OR(E20="",E20=0),"",I20/E20) | K20: =IF(E20="","",E20-I20) | L20: =IF(MAXIFS(Daily_Entry!$A$5:$A$1000,Daily_Entry!$B$5:$B$1000,"Ambient",Daily_Entry!$D$5:$D$1000,C20)=0,"",MAXIFS(Daily_Entry!$A$5:$A$1000,Daily_Entry!$B$5:$B$1000,"Ambient",Daily_Entry!$D$5:$D$1000,C20)) | M20: =IF(I20=0,"Not Started",IF(AND(E20<>"",I20>=E20),"Completed","In Progress")) -> Not Started
A21: 15 | B21: Floor & Racking | C21: Floor & Racking Work | D21: Sq.m | I21: =SUMIFS(Daily_Entry!$F$5:$F$1000,Daily_Entry!$B$5:$B$1000,"Ambient",Daily_Entry!$D$5:$D$1000,C21) -> 0 | J21: =IF(OR(E21="",E21=0),"",I21/E21) | K21: =IF(E21="","",E21-I21) | L21: =IF(MAXIFS(Daily_Entry!$A$5:$A$1000,Daily_Entry!$B$5:$B$1000,"Ambient",Daily_Entry!$D$5:$D$1000,C21)=0,"",MAXIFS(Daily_Entry!$A$5:$A$1000,Daily_Entry!$B$5:$B$1000,"Ambient",Daily_Entry!$D$5:$D$1000,C21)) | M21: =IF(I21=0,"Not Started",IF(AND(E21<>"",I21>=E21),"Completed","In Progress")) -> Not Started

Sheet Chiller Room
A1: CHILLER ROOM - SCOPE & PROGRESS TRACKER
A4: Room Overall % Complete: | D4: =IFERROR(AVERAGE(J7:J21),0) -> 0 | E4: Planned Handover Date: | G4: =IF(COUNT(H7:H21)=0,"",MIN(H7:H21)) | H4: Status: | I4: =IF(D4=1,"Ready for Handover",IF(D4>=0.75,"Near Completion",IF(D4>0,"In Progress","Not Started"))) -> Not Started
A6: S.No | B6: Category | C6: Item / Activity | D6: UOM | E6: Target Qty | F6: Planned Start | G6: Planned Finish | H6: Planned Handover | I6: Cumulative Qty Done | J6: % Complete | K6: Balance Qty | L6: Last Updated | M6: Status | N6: Remarks
A7: 1 | B7: PUF Panel | C7: Front Wall | D7: Sq.m | I7: =SUMIFS(Daily_Entry!$F$5:$F$1000,Daily_Entry!$B$5:$B$1000,"Chiller",Daily_Entry!$D$5:$D$1000,C7) -> 36 | J7: =IF(OR(E7="",E7=0),"",I7/E7) | K7: =IF(E7="","",E7-I7) | L7: =IF(MAXIFS(Daily_Entry!$A$5:$A$1000,Daily_Entry!$B$5:$B$1000,"Chiller",Daily_Entry!$D$5:$D$1000,C7)=0,"",MAXIFS(Daily_Entry!$A$5:$A$1000,Daily_Entry!$B$5:$B$1000,"Chiller",Daily_Entry!$D$5:$D$1000,C7)) -> 46186 | M7: =IF(I7=0,"Not Started",IF(AND(E7<>"",I7>=E7),"Completed","In Progress")) -> In Progress
A8: 2 | B8: PUF Panel | C8: Back Wall | D8: Sq.m | I8: =SUMIFS(Daily_Entry!$F$5:$F$1000,Daily_Entry!$B$5:$B$1000,"Chiller",Daily_Entry!$D$5:$D$1000,C8) -> 0 | J8: =IF(OR(E8="",E8=0),"",I8/E8) | K8: =IF(E8="","",E8-I8) | L8: =IF(MAXIFS(Daily_Entry!$A$5:$A$1000,Daily_Entry!$B$5:$B$1000,"Chiller",Daily_Entry!$D$5:$D$1000,C8)=0,"",MAXIFS(Daily_Entry!$A$5:$A$1000,Daily_Entry!$B$5:$B$1000,"Chiller",Daily_Entry!$D$5:$D$1000,C8)) | M8: =IF(I8=0,"Not Started",IF(AND(E8<>"",I8>=E8),"Completed","In Progress")) -> Not Started
A9: 3 | B9: PUF Panel | C9: Left Side Wall | D9: Sq.m | I9: =SUMIFS(Daily_Entry!$F$5:$F$1000,Daily_Entry!$B$5:$B$1000,"Chiller",Daily_Entry!$D$5:$D$1000,C9) -> 0 | J9: =IF(OR(E9="",E9=0),"",I9/E9) | K9: =IF(E9="","",E9-I9) | L9: =IF(MAXIFS(Daily_Entry!$A$5:$A$1000,Daily_Entry!$B$5:$B$1000,"Chiller",Daily_Entry!$D$5:$D$1000,C9)=0,"",MAXIFS(Daily_Entry!$A$5:$A$1000,Daily_Entry!$B$5:$B$1000,"Chiller",Daily_Entry!$D$5:$D$1000,C9)) | M9: =IF(I9=0,"Not Started",IF(AND(E9<>"",I9>=E9),"Completed","In Progress")) -> Not Started
A10: 4 | B10: PUF Panel | C10: Right Side Wall | D10: Sq.m | I10: =SUMIFS(Daily_Entry!$F$5:$F$1000,Daily_Entry!$B$5:$B$1000,"Chiller",Daily_Entry!$D$5:$D$1000,C10) -> 0 | J10: =IF(OR(E10="",E10=0),"",I10/E10) | K10: =IF(E10="","",E10-I10) | L10: =IF(MAXIFS(Daily_Entry!$A$5:$A$1000,Daily_Entry!$B$5:$B$1000,"Chiller",Daily_Entry!$D$5:$D$1000,C10)=0,"",MAXIFS(Daily_Entry!$A$5:$A$1000,Daily_Entry!$B$5:$B$1000,"Chiller",Daily_Entry!$D$5:$D$1000,C10)) | M10: =IF(I10=0,"Not Started",IF(AND(E10<>"",I10>=E10),"Completed","In Progress")) -> Not Started
A11: 5 | B11: PUF Panel | C11: Top Ceiling | D11: Sq.m | I11: =SUMIFS(Daily_Entry!$F$5:$F$1000,Daily_Entry!$B$5:$B$1000,"Chiller",Daily_Entry!$D$5:$D$1000,C11) -> 0 | J11: =IF(OR(E11="",E11=0),"",I11/E11) | K11: =IF(E11="","",E11-I11) | L11: =IF(MAXIFS(Daily_Entry!$A$5:$A$1000,Daily_Entry!$B$5:$B$1000,"Chiller",Daily_Entry!$D$5:$D$1000,C11)=0,"",MAXIFS(Daily_Entry!$A$5:$A$1000,Daily_Entry!$B$5:$B$1000,"Chiller",Daily_Entry!$D$5:$D$1000,C11)) | M11: =IF(I11=0,"Not Started",IF(AND(E11<>"",I11>=E11),"Completed","In Progress")) -> Not Started
A12: 6 | B12: PUF Panel | C12: PUF Slab (Floor) | D12: Sq.m | I12: =SUMIFS(Daily_Entry!$F$5:$F$1000,Daily_Entry!$B$5:$B$1000,"Chiller",Daily_Entry!$D$5:$D$1000,C12) -> 0 | J12: =IF(OR(E12="",E12=0),"",I12/E12) | K12: =IF(E12="","",E12-I12) | L12: =IF(MAXIFS(Daily_Entry!$A$5:$A$1000,Daily_Entry!$B$5:$B$1000,"Chiller",Daily_Entry!$D$5:$D$1000,C12)=0,"",MAXIFS(Daily_Entry!$A$5:$A$1000,Daily_Entry!$B$5:$B$1000,"Chiller",Daily_Entry!$D$5:$D$1000,C12)) | M12: =IF(I12=0,"Not Started",IF(AND(E12<>"",I12>=E12),"Completed","In Progress")) -> Not Started
A13: 7 | B13: PUF Panel | C13: Door Cutting | D13: Nos | I13: =SUMIFS(Daily_Entry!$F$5:$F$1000,Daily_Entry!$B$5:$B$1000,"Chiller",Daily_Entry!$D$5:$D$1000,C13) -> 0 | J13: =IF(OR(E13="",E13=0),"",I13/E13) | K13: =IF(E13="","",E13-I13) | L13: =IF(MAXIFS(Daily_Entry!$A$5:$A$1000,Daily_Entry!$B$5:$B$1000,"Chiller",Daily_Entry!$D$5:$D$1000,C13)=0,"",MAXIFS(Daily_Entry!$A$5:$A$1000,Daily_Entry!$B$5:$B$1000,"Chiller",Daily_Entry!$D$5:$D$1000,C13)) | M13: =IF(I13=0,"Not Started",IF(AND(E13<>"",I13>=E13),"Completed","In Progress")) -> Not Started
A14: 8 | B14: PUF Panel | C14: Silicon Filling - Inside | D14: Rmt | I14: =SUMIFS(Daily_Entry!$F$5:$F$1000,Daily_Entry!$B$5:$B$1000,"Chiller",Daily_Entry!$D$5:$D$1000,C14) -> 0 | J14: =IF(OR(E14="",E14=0),"",I14/E14) | K14: =IF(E14="","",E14-I14) | L14: =IF(MAXIFS(Daily_Entry!$A$5:$A$1000,Daily_Entry!$B$5:$B$1000,"Chiller",Daily_Entry!$D$5:$D$1000,C14)=0,"",MAXIFS(Daily_Entry!$A$5:$A$1000,Daily_Entry!$B$5:$B$1000,"Chiller",Daily_Entry!$D$5:$D$1000,C14)) | M14: =IF(I14=0,"Not Started",IF(AND(E14<>"",I14>=E14),"Completed","In Progress")) -> Not Started
A15: 9 | B15: PUF Panel | C15: Silicon Filling - Outside | D15: Rmt | I15: =SUMIFS(Daily_Entry!$F$5:$F$1000,Daily_Entry!$B$5:$B$1000,"Chiller",Daily_Entry!$D$5:$D$1000,C15) -> 0 | J15: =IF(OR(E15="",E15=0),"",I15/E15) | K15: =IF(E15="","",E15-I15) | L15: =IF(MAXIFS(Daily_Entry!$A$5:$A$1000,Daily_Entry!$B$5:$B$1000,"Chiller",Daily_Entry!$D$5:$D$1000,C15)=0,"",MAXIFS(Daily_Entry!$A$5:$A$1000,Daily_Entry!$B$5:$B$1000,"Chiller",Daily_Entry!$D$5:$D$1000,C15)) | M15: =IF(I15=0,"Not Started",IF(AND(E15<>"",I15>=E15),"Completed","In Progress")) -> Not Started
A16: 10 | B16: Door Work | C16: Door Installation | D16: Nos | I16: =SUMIFS(Daily_Entry!$F$5:$F$1000,Daily_Entry!$B$5:$B$1000,"Chiller",Daily_Entry!$D$5:$D$1000,C16) -> 0 | J16: =IF(OR(E16="",E16=0),"",I16/E16) | K16: =IF(E16="","",E16-I16) | L16: =IF(MAXIFS(Daily_Entry!$A$5:$A$1000,Daily_Entry!$B$5:$B$1000,"Chiller",Daily_Entry!$D$5:$D$1000,C16)=0,"",MAXIFS(Daily_Entry!$A$5:$A$1000,Daily_Entry!$B$5:$B$1000,"Chiller",Daily_Entry!$D$5:$D$1000,C16)) | M16: =IF(I16=0,"Not Started",IF(AND(E16<>"",I16>=E16),"Completed","In Progress")) -> Not Started
A17: 11 | B17: Door Work | C17: Falcon Sensor Installation | D17: Nos | I17: =SUMIFS(Daily_Entry!$F$5:$F$1000,Daily_Entry!$B$5:$B$1000,"Chiller",Daily_Entry!$D$5:$D$1000,C17) -> 0 | J17: =IF(OR(E17="",E17=0),"",I17/E17) | K17: =IF(E17="","",E17-I17) | L17: =IF(MAXIFS(Daily_Entry!$A$5:$A$1000,Daily_Entry!$B$5:$B$1000,"Chiller",Daily_Entry!$D$5:$D$1000,C17)=0,"",MAXIFS(Daily_Entry!$A$5:$A$1000,Daily_Entry!$B$5:$B$1000,"Chiller",Daily_Entry!$D$5:$D$1000,C17)) | M17: =IF(I17=0,"Not Started",IF(AND(E17<>"",I17>=E17),"Completed","In Progress")) -> Not Started
A18: 12 | B18: Door Work | C18: Air Curtain Installation | D18: Nos | I18: =SUMIFS(Daily_Entry!$F$5:$F$1000,Daily_Entry!$B$5:$B$1000,"Chiller",Daily_Entry!$D$5:$D$1000,C18) -> 0 | J18: =IF(OR(E18="",E18=0),"",I18/E18) | K18: =IF(E18="","",E18-I18) | L18: =IF(MAXIFS(Daily_Entry!$A$5:$A$1000,Daily_Entry!$B$5:$B$1000,"Chiller",Daily_Entry!$D$5:$D$1000,C18)=0,"",MAXIFS(Daily_Entry!$A$5:$A$1000,Daily_Entry!$B$5:$B$1000,"Chiller",Daily_Entry!$D$5:$D$1000,C18)) | M18: =IF(I18=0,"Not Started",IF(AND(E18<>"",I18>=E18),"Completed","In Progress")) -> Not Started
... A21: 15 | B21: Floor & Racking | C21: Floor & Racking Work | D21: Sq.m | I21: =SUMIFS(Daily_Entry!$F$5:$F$1000,Daily_Entry!$B$5:$B$1000,"Chiller",Daily_Entry!$D$5:$D$1000,C21) -> 0 | J21: =IF(OR(E21="",E21=0),"",I21/E21) | K21: =IF(E21="","",E21-I21) | L21: =IF(MAXIFS(Daily_Entry!$A$5:$A$1000,Daily_Entry!$B$5:$B$1000,"Chiller",Daily_Entry!$D$5:$D$1000,C21)=0,"",MAXIFS(Daily_Entry!$A$5:$A$1000,Daily_Entry!$B$5:$B$1000,"Chiller",Daily_Entry!$D$5:$D$1000,C21)) | M21: =IF(I21=0,"Not Started",IF(AND(E21<>"",I21>=E21),"Completed","In Progress")) -> Not Started

Sheet Freezer Room
A1: FREEZER ROOM - SCOPE & PROGRESS TRACKER
A4: Room Overall % Complete: | D4: =IFERROR(AVERAGE(J7:J21),0) -> 0 | E4: Planned Handover Date: | G4: =IF(COUNT(H7:H21)=0,"",MIN(H7:H21)) | H4: Status: | I4: =IF(D4=1,"Ready for Handover",IF(D4>=0.75,"Near Completion",IF(D4>0,"In Progress","Not Started"))) -> Not Started
A6: S.No | B6: Category | C6: Item / Activity | D6: UOM | E6: Target Qty | F6: Planned Start | G6: Planned Finish | H6: Planned Handover | I6: Cumulative Qty Done | J6: % Complete | K6: Balance Qty | L6: Last Updated | M6: Status | N6: Remarks
A7: 1 | B7: PUF Panel | C7: Front Wall | D7: Sq.m | I7: =SUMIFS(Daily_Entry!$F$5:$F$1000,Daily_Entry!$B$5:$B$1000,"Freezer",Daily_Entry!$D$5:$D$1000,C7) -> 0 | J7: =IF(OR(E7="",E7=0),"",I7/E7) | K7: =IF(E7="","",E7-I7) | L7: =IF(MAXIFS(Daily_Entry!$A$5:$A$1000,Daily_Entry!$B$5:$B$1000,"Freezer",Daily_Entry!$D$5:$D$1000,C7)=0,"",MAXIFS(Daily_Entry!$A$5:$A$1000,Daily_Entry!$B$5:$B$1000,"Freezer",Daily_Entry!$D$5:$D$1000,C7)) | M7: =IF(I7=0,"Not Started",IF(AND(E7<>"",I7>=E7),"Completed","In Progress")) -> Not Started
A8: 2 | B8: PUF Panel | C8: Back Wall | D8: Sq.m | I8: =SUMIFS(Daily_Entry!$F$5:$F$1000,Daily_Entry!$B$5:$B$1000,"Freezer",Daily_Entry!$D$5:$D$1000,C8) -> 0 | J8: =IF(OR(E8="",E8=0),"",I8/E8) | K8: =IF(E8="","",E8-I8) | L8: =IF(MAXIFS(Daily_Entry!$A$5:$A$1000,Daily_Entry!$B$5:$B$1000,"Freezer",Daily_Entry!$D$5:$D$1000,C8)=0,"",MAXIFS(Daily_Entry!$A$5:$A$1000,Daily_Entry!$B$5:$B$1000,"Freezer",Daily_Entry!$D$5:$D$1000,C8)) | M8: =IF(I8=0,"Not Started",IF(AND(E8<>"",I8>=E8),"Completed","In Progress")) -> Not Started
A9: 3 | B9: PUF Panel | C9: Left Side Wall | D9: Sq.m | I9: =SUMIFS(Daily_Entry!$F$5:$F$1000,Daily_Entry!$B$5:$B$1000,"Freezer",Daily_Entry!$D$5:$D$1000,C9) -> 0 | J9: =IF(OR(E9="",E9=0),"",I9/E9) | K9: =IF(E9="","",E9-I9) | L9: =IF(MAXIFS(Daily_Entry!$A$5:$A$1000,Daily_Entry!$B$5:$B$1000,"Freezer",Daily_Entry!$D$5:$D$1000,C9)=0,"",MAXIFS(Daily_Entry!$A$5:$A$1000,Daily_Entry!$B$5:$B$1000,"Freezer",Daily_Entry!$D$5:$D$1000,C9)) | M9: =IF(I9=0,"Not Started",IF(AND(E9<>"",I9>=E9),"Completed","In Progress")) -> Not Started
A10: 4 | B10: PUF Panel | C10: Right Side Wall | D10: Sq.m | I10: =SUMIFS(Daily_Entry!$F$5:$F$1000,Daily_Entry!$B$5:$B$1000,"Freezer",Daily_Entry!$D$5:$D$1000,C10) -> 0 | J10: =IF(OR(E10="",E10=0),"",I10/E10) | K10: =IF(E10="","",E10-I10) | L10: =IF(MAXIFS(Daily_Entry!$A$5:$A$1000,Daily_Entry!$B$5:$B$1000,"Freezer",Daily_Entry!$D$5:$D$1000,C10)=0,"",MAXIFS(Daily_Entry!$A$5:$A$1000,Daily_Entry!$B$5:$B$1000,"Freezer",Daily_Entry!$D$5:$D$1000,C10)) | M10: =IF(I10=0,"Not Started",IF(AND(E10<>"",I10>=E10),"Completed","In Progress")) -> Not Started
A11: 5 | B11: PUF Panel | C11: Top Ceiling | D11: Sq.m | I11: =SUMIFS(Daily_Entry!$F$5:$F$1000,Daily_Entry!$B$5:$B$1000,"Freezer",Daily_Entry!$D$5:$D$1000,C11) -> 0 | J11: =IF(OR(E11="",E11=0),"",I11/E11) | K11: =IF(E11="","",E11-I11) | L11: =IF(MAXIFS(Daily_Entry!$A$5:$A$1000,Daily_Entry!$B$5:$B$1000,"Freezer",Daily_Entry!$D$5:$D$1000,C11)=0,"",MAXIFS(Daily_Entry!$A$5:$A$1000,Daily_Entry!$B$5:$B$1000,"Freezer",Daily_Entry!$D$5:$D$1000,C11)) | M11: =IF(I11=0,"Not Started",IF(AND(E11<>"",I11>=E11),"Completed","In Progress")) -> Not Started
A12: 6 | B12: PUF Panel | C12: PUF Slab (Floor) | D12: Sq.m | I12: =SUMIFS(Daily_Entry!$F$5:$F$1000,Daily_Entry!$B$5:$B$1000,"Freezer",Daily_Entry!$D$5:$D$1000,C12) -> 0 | J12: =IF(OR(E12="",E12=0),"",I12/E12) | K12: =IF(E12="","",E12-I12) | L12: =IF(MAXIFS(Daily_Entry!$A$5:$A$1000,Daily_Entry!$B$5:$B$1000,"Freezer",Daily_Entry!$D$5:$D$1000,C12)=0,"",MAXIFS(Daily_Entry!$A$5:$A$1000,Daily_Entry!$B$5:$B$1000,"Freezer",Daily_Entry!$D$5:$D$1000,C12)) | M12: =IF(I12=0,"Not Started",IF(AND(E12<>"",I12>=E12),"Completed","In Progress")) -> Not Started
A13: 7 | B13: PUF Panel | C13: Door Cutting | D13: Nos | I13: =SUMIFS(Daily_Entry!$F$5:$F$1000,Daily_Entry!$B$5:$B$1000,"Freezer",Daily_Entry!$D$5:$D$1000,C13) -> 0 | J13: =IF(OR(E13="",E13=0),"",I13/E13) | K13: =IF(E13="","",E13-I13) | L13: =IF(MAXIFS(Daily_Entry!$A$5:$A$1000,Daily_Entry!$B$5:$B$1000,"Freezer",Daily_Entry!$D$5:$D$1000,C13)=0,"",MAXIFS(Daily_Entry!$A$5:$A$1000,Daily_Entry!$B$5:$B$1000,"Freezer",Daily_Entry!$D$5:$D$1000,C13)) | M13: =IF(I13=0,"Not Started",IF(AND(E13<>"",I13>=E13),"Completed","In Progress")) -> Not Started
A14: 8 | B14: PUF Panel | C14: Silicon Filling - Inside | D14: Rmt | I14: =SUMIFS(Daily_Entry!$F$5:$F$1000,Daily_Entry!$B$5:$B$1000,"Freezer",Daily_Entry!$D$5:$D$1000,C14) -> 0 | J14: =IF(OR(E14="",E14=0),"",I14/E14) | K14: =IF(E14="","",E14-I14) | L14: =IF(MAXIFS(Daily_Entry!$A$5:$A$1000,Daily_Entry!$B$5:$B$1000,"Freezer",Daily_Entry!$D$5:$D$1000,C14)=0,"",MAXIFS(Daily_Entry!$A$5:$A$1000,Daily_Entry!$B$5:$B$1000,"Freezer",Daily_Entry!$D$5:$D$1000,C14)) | M14: =IF(I14=0,"Not Started",IF(AND(E14<>"",I14>=E14),"Completed","In Progress")) -> Not Started
A15: 9 | B15: PUF Panel | C15: Silicon Filling - Outside | D15: Rmt | I15: =SUMIFS(Daily_Entry!$F$5:$F$1000,Daily_Entry!$B$5:$B$1000,"Freezer",Daily_Entry!$D$5:$D$1000,C15) -> 0 | J15: =IF(OR(E15="",E15=0),"",I15/E15) | K15: =IF(E15="","",E15-I15) | L15: =IF(MAXIFS(Daily_Entry!$A$5:$A$1000,Daily_Entry!$B$5:$B$1000,"Freezer",Daily_Entry!$D$5:$D$1000,C15)=0,"",MAXIFS(Daily_Entry!$A$5:$A$1000,Daily_Entry!$B$5:$B$1000,"Freezer",Daily_Entry!$D$5:$D$1000,C15)) | M15: =IF(I15=0,"Not Started",IF(AND(E15<>"",I15>=E15),"Completed","In Progress")) -> Not Started
A16: 10 | B16: Door Work | C16: Door Installation | D16: Nos | I16: =SUMIFS(Daily_Entry!$F$5:$F$1000,Daily_Entry!$B$5:$B$1000,"Freezer",Daily_Entry!$D$5:$D$1000,C16) -> 0 | J16: =IF(OR(E16="",E16=0),"",I16/E16) | K16: =IF(E16="","",E16-I16) | L16: =IF(MAXIFS(Daily_Entry!$A$5:$A$1000,Daily_Entry!$B$5:$B$1000,"Freezer",Daily_Entry!$D$5:$D$1000,C16)=0,"",MAXIFS(Daily_Entry!$A$5:$A$1000,Daily_Entry!$B$5:$B$1000,"Freezer",Daily_Entry!$D$5:$D$1000,C16)) | M16: =IF(I16=0,"Not Started",IF(AND(E16<>"",I16>=E16),"Completed","In Progress")) -> Not Started
A17: 11 | B17: Door Work | C17: Falcon Sensor Installation | D17: Nos | I17: =SUMIFS(Daily_Entry!$F$5:$F$1000,Daily_Entry!$B$5:$B$1000,"Freezer",Daily_Entry!$D$5:$D$1000,C17) -> 0 | J17: =IF(OR(E17="",E17=0),"",I17/E17) | K17: =IF(E17="","",E17-I17) | L17: =IF(MAXIFS(Daily_Entry!$A$5:$A$1000,Daily_Entry!$B$5:$B$1000,"Freezer",Daily_Entry!$D$5:$D$1000,C17)=0,"",MAXIFS(Daily_Entry!$A$5:$A$1000,Daily_Entry!$B$5:$B$1000,"Freezer",Daily_Entry!$D$5:$D$1000,C17)) | M17: =IF(I17=0,"Not Started",IF(AND(E17<>"",I17>=E17),"Completed","In Progress")) -> Not Started
A18: 12 | B18: Door Work | C18: Air Curtain Installation | D18: Nos | I18: =SUMIFS(Daily_Entry!$F$5:$F$1000,Daily_Entry!$B$5:$B$1000,"Freezer",Daily_Entry!$D$5:$D$1000,C18) -> 0 | J18: =IF(OR(E18="",E18=0),"",I18/E18) | K18: =IF(E18="","",E18-I18) | L18: =IF(MAXIFS(Daily_Entry!$A$5:$A$1000,Daily_Entry!$B$5:$B$1000,"Freezer",Daily_Entry!$D$5:$D$1000,C18)=0,"",MAXIFS(Daily_Entry!$A$5:$A$1000,Daily_Entry!$B$5:$B$1000,"Freezer",Daily_Entry!$D$5:$D$1000,C18)) | M18: =IF(I18=0,"Not Started",IF(AND(E18<>"",I18>=E18),"Completed","In Progress")) -> Not Started
... A21: 15 | B21: Floor & Racking | C21: Floor & Racking Work | D21: Sq.m | I21: =SUMIFS(Daily_Entry!$F$5:$F$1000,Daily_Entry!$B$5:$B$1000,"Freezer",Daily_Entry!$D$5:$D$1000,C21) -> 0 | J21: =IF(OR(E21="",E21=0),"",I21/E21) | K21: =IF(E21="","",E21-I21) | L21: =IF(MAXIFS(Daily_Entry!$A$5:$A$1000,Daily_Entry!$B$5:$B$1000,"Freezer",Daily_Entry!$D$5:$D$1000,C21)=0,"",MAXIFS(Daily_Entry!$A$5:$A$1000,Daily_Entry!$B$5:$B$1000,"Freezer",Daily_Entry!$D$5:$D$1000,C21)) | M21: =IF(I21=0,"Not Started",IF(AND(E21<>"",I21>=E21),"Completed","In Progress")) -> Not Started

Sheet Blast Room
A1: BLAST ROOM - SCOPE & PROGRESS TRACKER
A4: Room Overall % Complete: | D4: =IFERROR(AVERAGE(J7:J21),0) -> 0 | E4: Planned Handover Date: | G4: =IF(COUNT(H7:H21)=0,"",MIN(H7:H21)) | H4: Status: | I4: =IF(D4=1,"Ready for Handover",IF(D4>=0.75,"Near Completion",IF(D4>0,"In Progress","Not Started"))) -> Not Started
A6: S.No | B6: Category | C6: Item / Activity | D6: UOM | E6: Target Qty | F6: Planned Start | G6: Planned Finish | H6: Planned Handover | I6: Cumulative Qty Done | J6: % Complete | K6: Balance Qty | L6: Last Updated | M6: Status | N6: Remarks
A7: 1 | B7: PUF Panel | C7: Front Wall | D7: Sq.m | I7: =SUMIFS(Daily_Entry!$F$5:$F$1000,Daily_Entry!$B$5:$B$1000,"Blast",Daily_Entry!$D$5:$D$1000,C7) -> 0 | J7: =IF(OR(E7="",E7=0),"",I7/E7) | K7: =IF(E7="","",E7-I7) | L7: =IF(MAXIFS(Daily_Entry!$A$5:$A$1000,Daily_Entry!$B$5:$B$1000,"Blast",Daily_Entry!$D$5:$D$1000,C7)=0,"",MAXIFS(Daily_Entry!$A$5:$A$1000,Daily_Entry!$B$5:$B$1000,"Blast",Daily_Entry!$D$5:$D$1000,C7)) | M7: =IF(I7=0,"Not Started",IF(AND(E7<>"",I7>=E7),"Completed","In Progress")) -> Not Started
A8: 2 | B8: PUF Panel | C8: Back Wall | D8: Sq.m | I8: =SUMIFS(Daily_Entry!$F$5:$F$1000,Daily_Entry!$B$5:$B$1000,"Blast",Daily_Entry!$D$5:$D$1000,C8) -> 0 | J8: =IF(OR(E8="",E8=0),"",I8/E8) | K8: =IF(E8="","",E8-I8) | L8: =IF(MAXIFS(Daily_Entry!$A$5:$A$1000,Daily_Entry!$B$5:$B$1000,"Blast",Daily_Entry!$D$5:$D$1000,C8)=0,"",MAXIFS(Daily_Entry!$A$5:$A$1000,Daily_Entry!$B$5:$B$1000,"Blast",Daily_Entry!$D$5:$D$1000,C8)) | M8: =IF(I8=0,"Not Started",IF(AND(E8<>"",I8>=E8),"Completed","In Progress")) -> Not Started
A9: 3 | B9: PUF Panel | C9: Left Side Wall | D9: Sq.m | I9: =SUMIFS(Daily_Entry!$F$5:$F$1000,Daily_Entry!$B$5:$B$1000,"Blast",Daily_Entry!$D$5:$D$1000,C9) -> 0 | J9: =IF(OR(E9="",E9=0),"",I9/E9) | K9: =IF(E9="","",E9-I9) | L9: =IF(MAXIFS(Daily_Entry!$A$5:$A$1000,Daily_Entry!$B$5:$B$1000,"Blast",Daily_Entry!$D$5:$D$1000,C9)=0,"",MAXIFS(Daily_Entry!$A$5:$A$1000,Daily_Entry!$B$5:$B$1000,"Blast",Daily_Entry!$D$5:$D$1000,C9)) | M9: =IF(I9=0,"Not Started",IF(AND(E9<>"",I9>=E9),"Completed","In Progress")) -> Not Started
A10: 4 | B10: PUF Panel | C10: Right Side Wall | D10: Sq.m | I10: =SUMIFS(Daily_Entry!$F$5:$F$1000,Daily_Entry!$B$5:$B$1000,"Blast",Daily_Entry!$D$5:$D$1000,C10) -> 0 | J10: =IF(OR(E10="",E10=0),"",I10/E10) | K10: =IF(E10="","",E10-I10) | L10: =IF(MAXIFS(Daily_Entry!$A$5:$A$1000,Daily_Entry!$B$5:$B$1000,"Blast",Daily_Entry!$D$5:$D$1000,C10)=0,"",MAXIFS(Daily_Entry!$A$5:$A$1000,Daily_Entry!$B$5:$B$1000,"Blast",Daily_Entry!$D$5:$D$1000,C10)) | M10: =IF(I10=0,"Not Started",IF(AND(E10<>"",I10>=E10),"Completed","In Progress")) -> Not Started
A11: 5 | B11: PUF Panel | C11: Top Ceiling | D11: Sq.m | I11: =SUMIFS(Daily_Entry!$F$5:$F$1000,Daily_Entry!$B$5:$B$1000,"Blast",Daily_Entry!$D$5:$D$1000,C11) -> 0 | J11: =IF(OR(E11="",E11=0),"",I11/E11) | K11: =IF(E11="","",E11-I11) | L11: =IF(MAXIFS(Daily_Entry!$A$5:$A$1000,Daily_Entry!$B$5:$B$1000,"Blast",Daily_Entry!$D$5:$D$1000,C11)=0,"",MAXIFS(Daily_Entry!$A$5:$A$1000,Daily_Entry!$B$5:$B$1000,"Blast",Daily_Entry!$D$5:$D$1000,C11)) | M11: =IF(I11=0,"Not Started",IF(AND(E11<>"",I11>=E11),"Completed","In Progress")) -> Not Started
A12: 6 | B12: PUF Panel | C12: PUF Slab (Floor) | D12: Sq.m | I12: =SUMIFS(Daily_Entry!$F$5:$F$1000,Daily_Entry!$B$5:$B$1000,"Blast",Daily_Entry!$D$5:$D$1000,C12) -> 0 | J12: =IF(OR(E12="",E12=0),"",I12/E12) | K12: =IF(E12="","",E12-I12) | L12: =IF(MAXIFS(Daily_Entry!$A$5:$A$1000,Daily_Entry!$B$5:$B$1000,"Blast",Daily_Entry!$D$5:$D$1000,C12)=0,"",MAXIFS(Daily_Entry!$A$5:$A$1000,Daily_Entry!$B$5:$B$1000,"Blast",Daily_Entry!$D$5:$D$1000,C12)) | M12: =IF(I12=0,"Not Started",IF(AND(E12<>"",I12>=E12),"Completed","In Progress")) -> Not Started
A13: 7 | B13: PUF Panel | C13: Door Cutting | D13: Nos | I13: =SUMIFS(Daily_Entry!$F$5:$F$1000,Daily_Entry!$B$5:$B$1000,"Blast",Daily_Entry!$D$5:$D$1000,C13) -> 0 | J13: =IF(OR(E13="",E13=0),"",I13/E13) | K13: =IF(E13="","",E13-I13) | L13: =IF(MAXIFS(Daily_Entry!$A$5:$A$1000,Daily_Entry!$B$5:$B$1000,"Blast",Daily_Entry!$D$5:$D$1000,C13)=0,"",MAXIFS(Daily_Entry!$A$5:$A$1000,Daily_Entry!$B$5:$B$1000,"Blast",Daily_Entry!$D$5:$D$1000,C13)) | M13: =IF(I13=0,"Not Started",IF(AND(E13<>"",I13>=E13),"Completed","In Progress")) -> Not Started
A14: 8 | B14: PUF Panel | C14: Silicon Filling - Inside | D14: Rmt | I14: =SUMIFS(Daily_Entry!$F$5:$F$1000,Daily_Entry!$B$5:$B$1000,"Blast",Daily_Entry!$D$5:$D$1000,C14) -> 0 | J14: =IF(OR(E14="",E14=0),"",I14/E14) | K14: =IF(E14="","",E14-I14) | L14: =IF(MAXIFS(Daily_Entry!$A$5:$A$1000,Daily_Entry!$B$5:$B$1000,"Blast",Daily_Entry!$D$5:$D$1000,C14)=0,"",MAXIFS(Daily_Entry!$A$5:$A$1000,Daily_Entry!$B$5:$B$1000,"Blast",Daily_Entry!$D$5:$D$1000,C14)) | M14: =IF(I14=0,"Not Started",IF(AND(E14<>"",I14>=E14),"Completed","In Progress")) -> Not Started
A15: 9 | B15: PUF Panel | C15: Silicon Filling - Outside | D15: Rmt | I15: =SUMIFS(Daily_Entry!$F$5:$F$1000,Daily_Entry!$B$5:$B$1000,"Blast",Daily_Entry!$D$5:$D$1000,C15) -> 0 | J15: =IF(OR(E15="",E15=0),"",I15/E15) | K15: =IF(E15="","",E15-I15) | L15: =IF(MAXIFS(Daily_Entry!$A$5:$A$1000,Daily_Entry!$B$5:$B$1000,"Blast",Daily_Entry!$D$5:$D$1000,C15)=0,"",MAXIFS(Daily_Entry!$A$5:$A$1000,Daily_Entry!$B$5:$B$1000,"Blast",Daily_Entry!$D$5:$D$1000,C15)) | M15: =IF(I15=0,"Not Started",IF(AND(E15<>"",I15>=E15),"Completed","In Progress")) -> Not Started
A16: 10 | B16: Door Work | C16: Door Installation | D16: Nos | I16: =SUMIFS(Daily_Entry!$F$5:$F$1000,Daily_Entry!$B$5:$B$1000,"Blast",Daily_Entry!$D$5:$D$1000,C16) -> 0 | J16: =IF(OR(E16="",E16=0),"",I16/E16) | K16: =IF(E16="","",E16-I16) | L16: =IF(MAXIFS(Daily_Entry!$A$5:$A$1000,Daily_Entry!$B$5:$B$1000,"Blast",Daily_Entry!$D$5:$D$1000,C16)=0,"",MAXIFS(Daily_Entry!$A$5:$A$1000,Daily_Entry!$B$5:$B$1000,"Blast",Daily_Entry!$D$5:$D$1000,C16)) | M16: =IF(I16=0,"Not Started",IF(AND(E16<>"",I16>=E16),"Completed","In Progress")) -> Not Started
A17: 11 | B17: Door Work | C17: Falcon Sensor Installation | D17: Nos | I17: =SUMIFS(Daily_Entry!$F$5:$F$1000,Daily_Entry!$B$5:$B$1000,"Blast",Daily_Entry!$D$5:$D$1000,C17) -> 0 | J17: =IF(OR(E17="",E17=0),"",I17/E17) | K17: =IF(E17="","",E17-I17) | L17: =IF(MAXIFS(Daily_Entry!$A$5:$A$1000,Daily_Entry!$B$5:$B$1000,"Blast",Daily_Entry!$D$5:$D$1000,C17)=0,"",MAXIFS(Daily_Entry!$A$5:$A$1000,Daily_Entry!$B$5:$B$1000,"Blast",Daily_Entry!$D$5:$D$1000,C17)) | M17: =IF(I17=0,"Not Started",IF(AND(E17<>"",I17>=E17),"Completed","In Progress")) -> Not Started
A18: 12 | B18: Door Work | C18: Air Curtain Installation | D18: Nos | I18: =SUMIFS(Daily_Entry!$F$5:$F$1000,Daily_Entry!$B$5:$B$1000,"Blast",Daily_Entry!$D$5:$D$1000,C18) -> 0 | J18: =IF(OR(E18="",E18=0),"",I18/E18) | K18: =IF(E18="","",E18-I18) | L18: =IF(MAXIFS(Daily_Entry!$A$5:$A$1000,Daily_Entry!$B$5:$B$1000,"Blast",Daily_Entry!$D$5:$D$1000,C18)=0,"",MAXIFS(Daily_Entry!$A$5:$A$1000,Daily_Entry!$B$5:$B$1000,"Blast",Daily_Entry!$D$5:$D$1000,C18)) | M18: =IF(I18=0,"Not Started",IF(AND(E18<>"",I18>=E18),"Completed","In Progress")) -> Not Started
... A21: 15 | B21: Floor & Racking | C21: Floor & Racking Work | D21: Sq.m | I21: =SUMIFS(Daily_Entry!$F$5:$F$1000,Daily_Entry!$B$5:$B$1000,"Blast",Daily_Entry!$D$5:$D$1000,C21) -> 0 | J21: =IF(OR(E21="",E21=0),"",I21/E21) | K21: =IF(E21="","",E21-I21) | L21: =IF(MAXIFS(Daily_Entry!$A$5:$A$1000,Daily_Entry!$B$5:$B$1000,"Blast",Daily_Entry!$D$5:$D$1000,C21)=0,"",MAXIFS(Daily_Entry!$A$5:$A$1000,Daily_Entry!$B$5:$B$1000,"Blast",Daily_Entry!$D$5:$D$1000,C21)) | M21: =IF(I21=0,"Not Started",IF(AND(E21<>"",I21>=E21),"Completed","In Progress")) -> Not Started

Sheet FNV Room
A1: FNV ROOM - SCOPE & PROGRESS TRACKER
A4: Room Overall % Complete: | D4: =IFERROR(AVERAGE(J7:J21),0) -> 0 | E4: Planned Handover Date: | G4: =IF(COUNT(H7:H21)=0,"",MIN(H7:H21)) | H4: Status: | I4: =IF(D4=1,"Ready for Handover",IF(D4>=0.75,"Near Completion",IF(D4>0,"In Progress","Not Started"))) -> Not Started
A6: S.No | B6: Category | C6: Item / Activity | D6: UOM | E6: Target Qty | F6: Planned Start | G6: Planned Finish | H6: Planned Handover | I6: Cumulative Qty Done | J6: % Complete | K6: Balance Qty | L6: Last Updated | M6: Status | N6: Remarks
A7: 1 | B7: PUF Panel | C7: Front Wall | D7: Sq.m | I7: =SUMIFS(Daily_Entry!$F$5:$F$1000,Daily_Entry!$B$5:$B$1000,"FNV",Daily_Entry!$D$5:$D$1000,C7) -> 0 | J7: =IF(OR(E7="",E7=0),"",I7/E7) | K7: =IF(E7="","",E7-I7) | L7: =IF(MAXIFS(Daily_Entry!$A$5:$A$1000,Daily_Entry!$B$5:$B$1000,"FNV",Daily_Entry!$D$5:$D$1000,C7)=0,"",MAXIFS(Daily_Entry!$A$5:$A$1000,Daily_Entry!$B$5:$B$1000,"FNV",Daily_Entry!$D$5:$D$1000,C7)) | M7: =IF(I7=0,"Not Started",IF(AND(E7<>"",I7>=E7),"Completed","In Progress")) -> Not Started
A8: 2 | B8: PUF Panel | C8: Back Wall | D8: Sq.m | I8: =SUMIFS(Daily_Entry!$F$5:$F$1000,Daily_Entry!$B$5:$B$1000,"FNV",Daily_Entry!$D$5:$D$1000,C8) -> 0 | J8: =IF(OR(E8="",E8=0),"",I8/E8) | K8: =IF(E8="","",E8-I8) | L8: =IF(MAXIFS(Daily_Entry!$A$5:$A$1000,Daily_Entry!$B$5:$B$1000,"FNV",Daily_Entry!$D$5:$D$1000,C8)=0,"",MAXIFS(Daily_Entry!$A$5:$A$1000,Daily_Entry!$B$5:$B$1000,"FNV",Daily_Entry!$D$5:$D$1000,C8)) | M8: =IF(I8=0,"Not Started",IF(AND(E8<>"",I8>=E8),"Completed","In Progress")) -> Not Started
A9: 3 | B9: PUF Panel | C9: Left Side Wall | D9: Sq.m | I9: =SUMIFS(Daily_Entry!$F$5:$F$1000,Daily_Entry!$B$5:$B$1000,"FNV",Daily_Entry!$D$5:$D$1000,C9) -> 0 | J9: =IF(OR(E9="",E9=0),"",I9/E9) | K9: =IF(E9="","",E9-I9) | L9: =IF(MAXIFS(Daily_Entry!$A$5:$A$1000,Daily_Entry!$B$5:$B$1000,"FNV",Daily_Entry!$D$5:$D$1000,C9)=0,"",MAXIFS(Daily_Entry!$A$5:$A$1000,Daily_Entry!$B$5:$B$1000,"FNV",Daily_Entry!$D$5:$D$1000,C9)) | M9: =IF(I9=0,"Not Started",IF(AND(E9<>"",I9>=E9),"Completed","In Progress")) -> Not Started
A10: 4 | B10: PUF Panel | C10: Right Side Wall | D10: Sq.m | I10: =SUMIFS(Daily_Entry!$F$5:$F$1000,Daily_Entry!$B$5:$B$1000,"FNV",Daily_Entry!$D$5:$D$1000,C10) -> 0 | J10: =IF(OR(E10="",E10=0),"",I10/E10) | K10: =IF(E10="","",E10-I10) | L10: =IF(MAXIFS(Daily_Entry!$A$5:$A$1000,Daily_Entry!$B$5:$B$1000,"FNV",Daily_Entry!$D$5:$D$1000,C10)=0,"",MAXIFS(Daily_Entry!$A$5:$A$1000,Daily_Entry!$B$5:$B$1000,"FNV",Daily_Entry!$D$5:$D$1000,C10)) | M10: =IF(I10=0,"Not Started",IF(AND(E10<>"",I10>=E10),"Completed","In Progress")) -> Not Started
A11: 5 | B11: PUF Panel | C11: Top Ceiling | D11: Sq.m | I11: =SUMIFS(Daily_Entry!$F$5:$F$1000,Daily_Entry!$B$5:$B$1000,"FNV",Daily_Entry!$D$5:$D$1000,C11) -> 0 | J11: =IF(OR(E11="",E11=0),"",I11/E11) | K11: =IF(E11="","",E11-I11) | L11: =IF(MAXIFS(Daily_Entry!$A$5:$A$1000,Daily_Entry!$B$5:$B$1000,"FNV",Daily_Entry!$D$5:$D$1000,C11)=0,"",MAXIFS(Daily_Entry!$A$5:$A$1000,Daily_Entry!$B$5:$B$1000,"FNV",Daily_Entry!$D$5:$D$1000,C11)) | M11: =IF(I11=0,"Not Started",IF(AND(E11<>"",I11>=E11),"Completed","In Progress")) -> Not Started
A12: 6 | B12: PUF Panel | C12: PUF Slab (Floor) | D12: Sq.m | I12: =SUMIFS(Daily_Entry!$F$5:$F$1000,Daily_Entry!$B$5:$B$1000,"FNV",Daily_Entry!$D$5:$D$1000,C12) -> 0 | J12: =IF(OR(E12="",E12=0),"",I12/E12) | K12: =IF(E12="","",E12-I12) | L12: =IF(MAXIFS(Daily_Entry!$A$5:$A$1000,Daily_Entry!$B$5:$B$1000,"FNV",Daily_Entry!$D$5:$D$1000,C12)=0,"",MAXIFS(Daily_Entry!$A$5:$A$1000,Daily_Entry!$B$5:$B$1000,"FNV",Daily_Entry!$D$5:$D$1000,C12)) | M12: =IF(I12=0,"Not Started",IF(AND(E12<>"",I12>=E12),"Completed","In Progress")) -> Not Started
A13: 7 | B13: PUF Panel | C13: Door Cutting | D13: Nos | I13: =SUMIFS(Daily_Entry!$F$5:$F$1000,Daily_Entry!$B$5:$B$1000,"FNV",Daily_Entry!$D$5:$D$1000,C13) -> 0 | J13: =IF(OR(E13="",E13=0),"",I13/E13) | K13: =IF(E13="","",E13-I13) | L13: =IF(MAXIFS(Daily_Entry!$A$5:$A$1000,Daily_Entry!$B$5:$B$1000,"FNV",Daily_Entry!$D$5:$D$1000,C13)=0,"",MAXIFS(Daily_Entry!$A$5:$A$1000,Daily_Entry!$B$5:$B$1000,"FNV",Daily_Entry!$D$5:$D$1000,C13)) | M13: =IF(I13=0,"Not Started",IF(AND(E13<>"",I13>=E13),"Completed","In Progress")) -> Not Started
A14: 8 | B14: PUF Panel | C14: Silicon Filling - Inside | D14: Rmt | I14: =SUMIFS(Daily_Entry!$F$5:$F$1000,Daily_Entry!$B$5:$B$1000,"FNV",Daily_Entry!$D$5:$D$1000,C14) -> 0 | J14: =IF(OR(E14="",E14=0),"",I14/E14) | K14: =IF(E14="","",E14-I14) | L14: =IF(MAXIFS(Daily_Entry!$A$5:$A$1000,Daily_Entry!$B$5:$B$1000,"FNV",Daily_Entry!$D$5:$D$1000,C14)=0,"",MAXIFS(Daily_Entry!$A$5:$A$1000,Daily_Entry!$B$5:$B$1000,"FNV",Daily_Entry!$D$5:$D$1000,C14)) | M14: =IF(I14=0,"Not Started",IF(AND(E14<>"",I14>=E14),"Completed","In Progress")) -> Not Started
A15: 9 | B15: PUF Panel | C15: Silicon Filling - Outside | D15: Rmt | I15: =SUMIFS(Daily_Entry!$F$5:$F$1000,Daily_Entry!$B$5:$B$1000,"FNV",Daily_Entry!$D$5:$D$1000,C15) -> 0 | J15: =IF(OR(E15="",E15=0),"",I15/E15) | K15: =IF(E15="","",E15-I15) | L15: =IF(MAXIFS(Daily_Entry!$A$5:$A$1000,Daily_Entry!$B$5:$B$1000,"FNV",Daily_Entry!$D$5:$D$1000,C15)=0,"",MAXIFS(Daily_Entry!$A$5:$A$1000,Daily_Entry!$B$5:$B$1000,"FNV",Daily_Entry!$D$5:$D$1000,C15)) | M15: =IF(I15=0,"Not Started",IF(AND(E15<>"",I15>=E15),"Completed","In Progress")) -> Not Started
A16: 10 | B16: Door Work | C16: Door Installation | D16: Nos | I16: =SUMIFS(Daily_Entry!$F$5:$F$1000,Daily_Entry!$B$5:$B$1000,"FNV",Daily_Entry!$D$5:$D$1000,C16) -> 0 | J16: =IF(OR(E16="",E16=0),"",I16/E16) | K16: =IF(E16="","",E16-I16) | L16: =IF(MAXIFS(Daily_Entry!$A$5:$A$1000,Daily_Entry!$B$5:$B$1000,"FNV",Daily_Entry!$D$5:$D$1000,C16)=0,"",MAXIFS(Daily_Entry!$A$5:$A$1000,Daily_Entry!$B$5:$B$1000,"FNV",Daily_Entry!$D$5:$D$1000,C16)) | M16: =IF(I16=0,"Not Started",IF(AND(E16<>"",I16>=E16),"Completed","In Progress")) -> Not Started
A17: 11 | B17: Door Work | C17: Falcon Sensor Installation | D17: Nos | I17: =SUMIFS(Daily_Entry!$F$5:$F$1000,Daily_Entry!$B$5:$B$1000,"FNV",Daily_Entry!$D$5:$D$1000,C17) -> 0 | J17: =IF(OR(E17="",E17=0),"",I17/E17) | K17: =IF(E17="","",E17-I17) | L17: =IF(MAXIFS(Daily_Entry!$A$5:$A$1000,Daily_Entry!$B$5:$B$1000,"FNV",Daily_Entry!$D$5:$D$1000,C17)=0,"",MAXIFS(Daily_Entry!$A$5:$A$1000,Daily_Entry!$B$5:$B$1000,"FNV",Daily_Entry!$D$5:$D$1000,C17)) | M17: =IF(I17=0,"Not Started",IF(AND(E17<>"",I17>=E17),"Completed","In Progress")) -> Not Started
A18: 12 | B18: Door Work | C18: Air Curtain Installation | D18: Nos | I18: =SUMIFS(Daily_Entry!$F$5:$F$1000,Daily_Entry!$B$5:$B$1000,"FNV",Daily_Entry!$D$5:$D$1000,C18) -> 0 | J18: =IF(OR(E18="",E18=0),"",I18/E18) | K18: =IF(E18="","",E18-I18) | L18: =IF(MAXIFS(Daily_Entry!$A$5:$A$1000,Daily_Entry!$B$5:$B$1000,"FNV",Daily_Entry!$D$5:$D$1000,C18)=0,"",MAXIFS(Daily_Entry!$A$5:$A$1000,Daily_Entry!$B$5:$B$1000,"FNV",Daily_Entry!$D$5:$D$1000,C18)) | M18: =IF(I18=0,"Not Started",IF(AND(E18<>"",I18>=E18),"Completed","In Progress")) -> Not Started
... A21: 15 | B21: Floor & Racking | C21: Floor & Racking Work | D21: Sq.m | I21: =SUMIFS(Daily_Entry!$F$5:$F$1000,Daily_Entry!$B$5:$B$1000,"FNV",Daily_Entry!$D$5:$D$1000,C21) -> 0 | J21: =IF(OR(E21="",E21=0),"",I21/E21) | K21: =IF(E21="","",E21-I21) | L21: =IF(MAXIFS(Daily_Entry!$A$5:$A$1000,Daily_Entry!$B$5:$B$1000,"FNV",Daily_Entry!$D$5:$D$1000,C21)=0,"",MAXIFS(Daily_Entry!$A$5:$A$1000,Daily_Entry!$B$5:$B$1000,"FNV",Daily_Entry!$D$5:$D$1000,C21)) | M21: =IF(I21=0,"Not Started",IF(AND(E21<>"",I21>=E21),"Completed","In Progress")) -> Not Started

Sheet Corridor & Warm Room
A1: CORRIDOR & WARM ROOM - SCOPE & PROGRESS TRACKER
A4: Room Overall % Complete: | D4: =IFERROR(AVERAGE(J7:J21),0) -> 0 | E4: Planned Handover Date: | G4: =IF(COUNT(H7:H21)=0,"",MIN(H7:H21)) | H4: Status: | I4: =IF(D4=1,"Ready for Handover",IF(D4>=0.75,"Near Completion",IF(D4>0,"In Progress","Not Started"))) -> Not Started
A6: S.No | B6: Category | C6: Item / Activity | D6: UOM | E6: Target Qty | F6: Planned Start | G6: Planned Finish | H6: Planned Handover | I6: Cumulative Qty Done | J6: % Complete | K6: Balance Qty | L6: Last Updated | M6: Status | N6: Remarks
A7: 1 | B7: PUF Panel | C7: Front Wall | D7: Sq.m | I7: =SUMIFS(Daily_Entry!$F$5:$F$1000,Daily_Entry!$B$5:$B$1000,"Corridor & Warm Room",Daily_Entry!$D$5:$D$1000,C7) -> 0 | J7: =IF(OR(E7="",E7=0),"",I7/E7) | K7: =IF(E7="","",E7-I7) | L7: =IF(MAXIFS(Daily_Entry!$A$5:$A$1000,Daily_Entry!$B$5:$B$1000,"Corridor & Warm Room",Daily_Entry!$D$5:$D$1000,C7)=0,"",MAXIFS(Daily_Entry!$A$5:$A$1000,Daily_Entry!$B$5:$B$1000,"Corridor & Warm Room",Daily_Entry!$D$5:$D$1000,C7)) | M7: =IF(I7=0,"Not Started",IF(AND(E7<>"",I7>=E7),"Completed","In Progress")) -> Not Started
A8: 2 | B8: PUF Panel | C8: Back Wall | D8: Sq.m | I8: =SUMIFS(Daily_Entry!$F$5:$F$1000,Daily_Entry!$B$5:$B$1000,"Corridor & Warm Room",Daily_Entry!$D$5:$D$1000,C8) -> 0 | J8: =IF(OR(E8="",E8=0),"",I8/E8) | K8: =IF(E8="","",E8-I8) | L8: =IF(MAXIFS(Daily_Entry!$A$5:$A$1000,Daily_Entry!$B$5:$B$1000,"Corridor & Warm Room",Daily_Entry!$D$5:$D$1000,C8)=0,"",MAXIFS(Daily_Entry!$A$5:$A$1000,Daily_Entry!$B$5:$B$1000,"Corridor & Warm Room",Daily_Entry!$D$5:$D$1000,C8)) | M8: =IF(I8=0,"Not Started",IF(AND(E8<>"",I8>=E8),"Completed","In Progress")) -> Not Started
A9: 3 | B9: PUF Panel | C9: Left Side Wall | D9: Sq.m | I9: =SUMIFS(Daily_Entry!$F$5:$F$1000,Daily_Entry!$B$5:$B$1000,"Corridor & Warm Room",Daily_Entry!$D$5:$D$1000,C9) -> 0 | J9: =IF(OR(E9="",E9=0),"",I9/E9) | K9: =IF(E9="","",E9-I9) | L9: =IF(MAXIFS(Daily_Entry!$A$5:$A$1000,Daily_Entry!$B$5:$B$1000,"Corridor & Warm Room",Daily_Entry!$D$5:$D$1000,C9)=0,"",MAXIFS(Daily_Entry!$A$5:$A$1000,Daily_Entry!$B$5:$B$1000,"Corridor & Warm Room",Daily_Entry!$D$5:$D$1000,C9)) | M9: =IF(I9=0,"Not Started",IF(AND(E9<>"",I9>=E9),"Completed","In Progress")) -> Not Started
A10: 4 | B10: PUF Panel | C10: Right Side Wall | D10: Sq.m | I10: =SUMIFS(Daily_Entry!$F$5:$F$1000,Daily_Entry!$B$5:$B$1000,"Corridor & Warm Room",Daily_Entry!$D$5:$D$1000,C10) -> 0 | J10: =IF(OR(E10="",E10=0),"",I10/E10) | K10: =IF(E10="","",E10-I10) | L10: =IF(MAXIFS(Daily_Entry!$A$5:$A$1000,Daily_Entry!$B$5:$B$1000,"Corridor & Warm Room",Daily_Entry!$D$5:$D$1000,C10)=0,"",MAXIFS(Daily_Entry!$A$5:$A$1000,Daily_Entry!$B$5:$B$1000,"Corridor & Warm Room",Daily_Entry!$D$5:$D$1000,C10)) | M10: =IF(I10=0,"Not Started",IF(AND(E10<>"",I10>=E10),"Completed","In Progress")) -> Not Started
A11: 5 | B11: PUF Panel | C11: Top Ceiling | D11: Sq.m | I11: =SUMIFS(Daily_Entry!$F$5:$F$1000,Daily_Entry!$B$5:$B$1000,"Corridor & Warm Room",Daily_Entry!$D$5:$D$1000,C11) -> 0 | J11: =IF(OR(E11="",E11=0),"",I11/E11) | K11: =IF(E11="","",E11-I11) | L11: =IF(MAXIFS(Daily_Entry!$A$5:$A$1000,Daily_Entry!$B$5:$B$1000,"Corridor & Warm Room",Daily_Entry!$D$5:$D$1000,C11)=0,"",MAXIFS(Daily_Entry!$A$5:$A$1000,Daily_Entry!$B$5:$B$1000,"Corridor & Warm Room",Daily_Entry!$D$5:$D$1000,C11)) | M11: =IF(I11=0,"Not Started",IF(AND(E11<>"",I11>=E11),"Completed","In Progress")) -> Not Started
A12: 6 | B12: PUF Panel | C12: PUF Slab (Floor) | D12: Sq.m | I12: =SUMIFS(Daily_Entry!$F$5:$F$1000,Daily_Entry!$B$5:$B$1000,"Corridor & Warm Room",Daily_Entry!$D$5:$D$1000,C12) -> 0 | J12: =IF(OR(E12="",E12=0),"",I12/E12) | K12: =IF(E12="","",E12-I12) | L12: =IF(MAXIFS(Daily_Entry!$A$5:$A$1000,Daily_Entry!$B$5:$B$1000,"Corridor & Warm Room",Daily_Entry!$D$5:$D$1000,C12)=0,"",MAXIFS(Daily_Entry!$A$5:$A$1000,Daily_Entry!$B$5:$B$1000,"Corridor & Warm Room",Daily_Entry!$D$5:$D$1000,C12)) | M12: =IF(I12=0,"Not Started",IF(AND(E12<>"",I12>=E12),"Completed","In Progress")) -> Not Started
A13: 7 | B13: PUF Panel | C13: Door Cutting | D13: Nos | I13: =SUMIFS(Daily_Entry!$F$5:$F$1000,Daily_Entry!$B$5:$B$1000,"Corridor & Warm Room",Daily_Entry!$D$5:$D$1000,C13) -> 0 | J13: =IF(OR(E13="",E13=0),"",I13/E13) | K13: =IF(E13="","",E13-I13) | L13: =IF(MAXIFS(Daily_Entry!$A$5:$A$1000,Daily_Entry!$B$5:$B$1000,"Corridor & Warm Room",Daily_Entry!$D$5:$D$1000,C13)=0,"",MAXIFS(Daily_Entry!$A$5:$A$1000,Daily_Entry!$B$5:$B$1000,"Corridor & Warm Room",Daily_Entry!$D$5:$D$1000,C13)) | M13: =IF(I13=0,"Not Started",IF(AND(E13<>"",I13>=E13),"Completed","In Progress")) -> Not Started
A14: 8 | B14: PUF Panel | C14: Silicon Filling - Inside | D14: Rmt | I14: =SUMIFS(Daily_Entry!$F$5:$F$1000,Daily_Entry!$B$5:$B$1000,"Corridor & Warm Room",Daily_Entry!$D$5:$D$1000,C14) -> 0 | J14: =IF(OR(E14="",E14=0),"",I14/E14) | K14: =IF(E14="","",E14-I14) | L14: =IF(MAXIFS(Daily_Entry!$A$5:$A$1000,Daily_Entry!$B$5:$B$1000,"Corridor & Warm Room",Daily_Entry!$D$5:$D$1000,C14)=0,"",MAXIFS(Daily_Entry!$A$5:$A$1000,Daily_Entry!$B$5:$B$1000,"Corridor & Warm Room",Daily_Entry!$D$5:$D$1000,C14)) | M14: =IF(I14=0,"Not Started",IF(AND(E14<>"",I14>=E14),"Completed","In Progress")) -> Not Started
A15: 9 | B15: PUF Panel | C15: Silicon Filling - Outside | D15: Rmt | I15: =SUMIFS(Daily_Entry!$F$5:$F$1000,Daily_Entry!$B$5:$B$1000,"Corridor & Warm Room",Daily_Entry!$D$5:$D$1000,C15) -> 0 | J15: =IF(OR(E15="",E15=0),"",I15/E15) | K15: =IF(E15="","",E15-I15) | L15: =IF(MAXIFS(Daily_Entry!$A$5:$A$1000,Daily_Entry!$B$5:$B$1000,"Corridor & Warm Room",Daily_Entry!$D$5:$D$1000,C15)=0,"",MAXIFS(Daily_Entry!$A$5:$A$1000,Daily_Entry!$B$5:$B$1000,"Corridor & Warm Room",Daily_Entry!$D$5:$D$1000,C15)) | M15: =IF(I15=0,"Not Started",IF(AND(E15<>"",I15>=E15),"Completed","In Progress")) -> Not Started
A16: 10 | B16: Door Work | C16: Door Installation | D16: Nos | I16: =SUMIFS(Daily_Entry!$F$5:$F$1000,Daily_Entry!$B$5:$B$1000,"Corridor & Warm Room",Daily_Entry!$D$5:$D$1000,C16) -> 0 | J16: =IF(OR(E16="",E16=0),"",I16/E16) | K16: =IF(E16="","",E16-I16) | L16: =IF(MAXIFS(Daily_Entry!$A$5:$A$1000,Daily_Entry!$B$5:$B$1000,"Corridor & Warm Room",Daily_Entry!$D$5:$D$1000,C16)=0,"",MAXIFS(Daily_Entry!$A$5:$A$1000,Daily_Entry!$B$5:$B$1000,"Corridor & Warm Room",Daily_Entry!$D$5:$D$1000,C16)) | M16: =IF(I16=0,"Not Started",IF(AND(E16<>"",I16>=E16),"Completed","In Progress")) -> Not Started
A17: 11 | B17: Door Work | C17: Falcon Sensor Installation | D17: Nos | I17: =SUMIFS(Daily_Entry!$F$5:$F$1000,Daily_Entry!$B$5:$B$1000,"Corridor & Warm Room",Daily_Entry!$D$5:$D$1000,C17) -> 0 | J17: =IF(OR(E17="",E17=0),"",I17/E17) | K17: =IF(E17="","",E17-I17) | L17: =IF(MAXIFS(Daily_Entry!$A$5:$A$1000,Daily_Entry!$B$5:$B$1000,"Corridor & Warm Room",Daily_Entry!$D$5:$D$1000,C17)=0,"",MAXIFS(Daily_Entry!$A$5:$A$1000,Daily_Entry!$B$5:$B$1000,"Corridor & Warm Room",Daily_Entry!$D$5:$D$1000,C17)) | M17: =IF(I17=0,"Not Started",IF(AND(E17<>"",I17>=E17),"Completed","In Progress")) -> Not Started
A18: 12 | B18: Door Work | C18: Air Curtain Installation | D18: Nos | I18: =SUMIFS(Daily_Entry!$F$5:$F$1000,Daily_Entry!$B$5:$B$1000,"Corridor & Warm Room",Daily_Entry!$D$5:$D$1000,C18) -> 0 | J18: =IF(OR(E18="",E18=0),"",I18/E18) | K18: =IF(E18="","",E18-I18) | L18: =IF(MAXIFS(Daily_Entry!$A$5:$A$1000,Daily_Entry!$B$5:$B$1000,"Corridor & Warm Room",Daily_Entry!$D$5:$D$1000,C18)=0,"",MAXIFS(Daily_Entry!$A$5:$A$1000,Daily_Entry!$B$5:$B$1000,"Corridor & Warm Room",Daily_Entry!$D$5:$D$1000,C18)) | M18: =IF(I18=0,"Not Started",IF(AND(E18<>"",I18>=E18),"Completed","In Progress")) -> Not Started
... A21: 15 | B21: Floor & Racking | C21: Floor & Racking Work | D21: Sq.m | I21: =SUMIFS(Daily_Entry!$F$5:$F$1000,Daily_Entry!$B$5:$B$1000,"Corridor & Warm Room",Daily_Entry!$D$5:$D$1000,C21) -> 0 | J21: =IF(OR(E21="",E21=0),"",I21/E21) | K21: =IF(E21="","",E21-I21) | L21: =IF(MAXIFS(Daily_Entry!$A$5:$A$1000,Daily_Entry!$B$5:$B$1000,"Corridor & Warm Room",Daily_Entry!$D$5:$D$1000,C21)=0,"",MAXIFS(Daily_Entry!$A$5:$A$1000,Daily_Entry!$B$5:$B$1000,"Corridor & Warm Room",Daily_Entry!$D$5:$D$1000,C21)) | M21: =IF(I21=0,"Not Started",IF(AND(E21<>"",I21>=E21),"Completed","In Progress")) -> Not Started

Sheet Ante Room
A1: ANTE ROOM - SCOPE & PROGRESS TRACKER
A4: Room Overall % Complete: | D4: =IFERROR(AVERAGE(J7:J21),0) -> 0 | E4: Planned Handover Date: | G4: =IF(COUNT(H7:H21)=0,"",MIN(H7:H21)) | H4: Status: | I4: =IF(D4=1,"Ready for Handover",IF(D4>=0.75,"Near Completion",IF(D4>0,"In Progress","Not Started"))) -> Not Started
A6: S.No | B6: Category | C6: Item / Activity | D6: UOM | E6: Target Qty | F6: Planned Start | G6: Planned Finish | H6: Planned Handover | I6: Cumulative Qty Done | J6: % Complete | K6: Balance Qty | L6: Last Updated | M6: Status | N6: Remarks
A7: 1 | B7: PUF Panel | C7: Front Wall | D7: Sq.m | I7: =SUMIFS(Daily_Entry!$F$5:$F$1000,Daily_Entry!$B$5:$B$1000,"Ante Room",Daily_Entry!$D$5:$D$1000,C7) -> 0 | J7: =IF(OR(E7="",E7=0),"",I7/E7) | K7: =IF(E7="","",E7-I7) | L7: =IF(MAXIFS(Daily_Entry!$A$5:$A$1000,Daily_Entry!$B$5:$B$1000,"Ante Room",Daily_Entry!$D$5:$D$1000,C7)=0,"",MAXIFS(Daily_Entry!$A$5:$A$1000,Daily_Entry!$B$5:$B$1000,"Ante Room",Daily_Entry!$D$5:$D$1000,C7)) | M7: =IF(I7=0,"Not Started",IF(AND(E7<>"",I7>=E7),"Completed","In Progress")) -> Not Started
A8: 2 | B8: PUF Panel | C8: Back Wall | D8: Sq.m | I8: =SUMIFS(Daily_Entry!$F$5:$F$1000,Daily_Entry!$B$5:$B$1000,"Ante Room",Daily_Entry!$D$5:$D$1000,C8) -> 0 | J8: =IF(OR(E8="",E8=0),"",I8/E8) | K8: =IF(E8="","",E8-I8) | L8: =IF(MAXIFS(Daily_Entry!$A$5:$A$1000,Daily_Entry!$B$5:$B$1000,"Ante Room",Daily_Entry!$D$5:$D$1000,C8)=0,"",MAXIFS(Daily_Entry!$A$5:$A$1000,Daily_Entry!$B$5:$B$1000,"Ante Room",Daily_Entry!$D$5:$D$1000,C8)) | M8: =IF(I8=0,"Not Started",IF(AND(E8<>"",I8>=E8),"Completed","In Progress")) -> Not Started
A9: 3 | B9: PUF Panel | C9: Left Side Wall | D9: Sq.m | I9: =SUMIFS(Daily_Entry!$F$5:$F$1000,Daily_Entry!$B$5:$B$1000,"Ante Room",Daily_Entry!$D$5:$D$1000,C9) -> 0 | J9: =IF(OR(E9="",E9=0),"",I9/E9) | K9: =IF(E9="","",E9-I9) | L9: =IF(MAXIFS(Daily_Entry!$A$5:$A$1000,Daily_Entry!$B$5:$B$1000,"Ante Room",Daily_Entry!$D$5:$D$1000,C9)=0,"",MAXIFS(Daily_Entry!$A$5:$A$1000,Daily_Entry!$B$5:$B$1000,"Ante Room",Daily_Entry!$D$5:$D$1000,C9)) | M9: =IF(I9=0,"Not Started",IF(AND(E9<>"",I9>=E9),"Completed","In Progress")) -> Not Started
A10: 4 | B10: PUF Panel | C10: Right Side Wall | D10: Sq.m | I10: =SUMIFS(Daily_Entry!$F$5:$F$1000,Daily_Entry!$B$5:$B$1000,"Ante Room",Daily_Entry!$D$5:$D$1000,C10) -> 0 | J10: =IF(OR(E10="",E10=0),"",I10/E10) | K10: =IF(E10="","",E10-I10) | L10: =IF(MAXIFS(Daily_Entry!$A$5:$A$1000,Daily_Entry!$B$5:$B$1000,"Ante Room",Daily_Entry!$D$5:$D$1000,C10)=0,"",MAXIFS(Daily_Entry!$A$5:$A$1000,Daily_Entry!$B$5:$B$1000,"Ante Room",Daily_Entry!$D$5:$D$1000,C10)) | M10: =IF(I10=0,"Not Started",IF(AND(E10<>"",I10>=E10),"Completed","In Progress")) -> Not Started
A11: 5 | B11: PUF Panel | C11: Top Ceiling | D11: Sq.m | I11: =SUMIFS(Daily_Entry!$F$5:$F$1000,Daily_Entry!$B$5:$B$1000,"Ante Room",Daily_Entry!$D$5:$D$1000,C11) -> 0 | J11: =IF(OR(E11="",E11=0),"",I11/E11) | K11: =IF(E11="","",E11-I11) | L11: =IF(MAXIFS(Daily_Entry!$A$5:$A$1000,Daily_Entry!$B$5:$B$1000,"Ante Room",Daily_Entry!$D$5:$D$1000,C11)=0,"",MAXIFS(Daily_Entry!$A$5:$A$1000,Daily_Entry!$B$5:$B$1000,"Ante Room",Daily_Entry!$D$5:$D$1000,C11)) | M11: =IF(I11=0,"Not Started",IF(AND(E11<>"",I11>=E11),"Completed","In Progress")) -> Not Started
A12: 6 | B12: PUF Panel | C12: PUF Slab (Floor) | D12: Sq.m | I12: =SUMIFS(Daily_Entry!$F$5:$F$1000,Daily_Entry!$B$5:$B$1000,"Ante Room",Daily_Entry!$D$5:$D$1000,C12) -> 0 | J12: =IF(OR(E12="",E12=0),"",I12/E12) | K12: =IF(E12="","",E12-I12) | L12: =IF(MAXIFS(Daily_Entry!$A$5:$A$1000,Daily_Entry!$B$5:$B$1000,"Ante Room",Daily_Entry!$D$5:$D$1000,C12)=0,"",MAXIFS(Daily_Entry!$A$5:$A$1000,Daily_Entry!$B$5:$B$1000,"Ante Room",Daily_Entry!$D$5:$D$1000,C12)) | M12: =IF(I12=0,"Not Started",IF(AND(E12<>"",I12>=E12),"Completed","In Progress")) -> Not Started
A13: 7 | B13: PUF Panel | C13: Door Cutting | D13: Nos | I13: =SUMIFS(Daily_Entry!$F$5:$F$1000,Daily_Entry!$B$5:$B$1000,"Ante Room",Daily_Entry!$D$5:$D$1000,C13) -> 0 | J13: =IF(OR(E13="",E13=0),"",I13/E13) | K13: =IF(E13="","",E13-I13) | L13: =IF(MAXIFS(Daily_Entry!$A$5:$A$1000,Daily_Entry!$B$5:$B$1000,"Ante Room",Daily_Entry!$D$5:$D$1000,C13)=0,"",MAXIFS(Daily_Entry!$A$5:$A$1000,Daily_Entry!$B$5:$B$1000,"Ante Room",Daily_Entry!$D$5:$D$1000,C13)) | M13: =IF(I13=0,"Not Started",IF(AND(E13<>"",I13>=E13),"Completed","In Progress")) -> Not Started
A14: 8 | B14: PUF Panel | C14: Silicon Filling - Inside | D14: Rmt | I14: =SUMIFS(Daily_Entry!$F$5:$F$1000,Daily_Entry!$B$5:$B$1000,"Ante Room",Daily_Entry!$D$5:$D$1000,C14) -> 0 | J14: =IF(OR(E14="",E14=0),"",I14/E14) | K14: =IF(E14="","",E14-I14) | L14: =IF(MAXIFS(Daily_Entry!$A$5:$A$1000,Daily_Entry!$B$5:$B$1000,"Ante Room",Daily_Entry!$D$5:$D$1000,C14)=0,"",MAXIFS(Daily_Entry!$A$5:$A$1000,Daily_Entry!$B$5:$B$1000,"Ante Room",Daily_Entry!$D$5:$D$1000,C14)) | M14: =IF(I14=0,"Not Started",IF(AND(E14<>"",I14>=E14),"Completed","In Progress")) -> Not Started
A15: 9 | B15: PUF Panel | C15: Silicon Filling - Outside | D15: Rmt | I15: =SUMIFS(Daily_Entry!$F$5:$F$1000,Daily_Entry!$B$5:$B$1000,"Ante Room",Daily_Entry!$D$5:$D$1000,C15) -> 0 | J15: =IF(OR(E15="",E15=0),"",I15/E15) | K15: =IF(E15="","",E15-I15) | L15: =IF(MAXIFS(Daily_Entry!$A$5:$A$1000,Daily_Entry!$B$5:$B$1000,"Ante Room",Daily_Entry!$D$5:$D$1000,C15)=0,"",MAXIFS(Daily_Entry!$A$5:$A$1000,Daily_Entry!$B$5:$B$1000,"Ante Room",Daily_Entry!$D$5:$D$1000,C15)) | M15: =IF(I15=0,"Not Started",IF(AND(E15<>"",I15>=E15),"Completed","In Progress")) -> Not Started
A16: 10 | B16: Door Work | C16: Door Installation | D16: Nos | I16: =SUMIFS(Daily_Entry!$F$5:$F$1000,Daily_Entry!$B$5:$B$1000,"Ante Room",Daily_Entry!$D$5:$D$1000,C16) -> 0 | J16: =IF(OR(E16="",E16=0),"",I16/E16) | K16: =IF(E16="","",E16-I16) | L16: =IF(MAXIFS(Daily_Entry!$A$5:$A$1000,Daily_Entry!$B$5:$B$1000,"Ante Room",Daily_Entry!$D$5:$D$1000,C16)=0,"",MAXIFS(Daily_Entry!$A$5:$A$1000,Daily_Entry!$B$5:$B$1000,"Ante Room",Daily_Entry!$D$5:$D$1000,C16)) | M16: =IF(I16=0,"Not Started",IF(AND(E16<>"",I16>=E16),"Completed","In Progress")) -> Not Started
A17: 11 | B17: Door Work | C17: Falcon Sensor Installation | D17: Nos | I17: =SUMIFS(Daily_Entry!$F$5:$F$1000,Daily_Entry!$B$5:$B$1000,"Ante Room",Daily_Entry!$D$5:$D$1000,C17) -> 0 | J17: =IF(OR(E17="",E17=0),"",I17/E17) | K17: =IF(E17="","",E17-I17) | L17: =IF(MAXIFS(Daily_Entry!$A$5:$A$1000,Daily_Entry!$B$5:$B$1000,"Ante Room",Daily_Entry!$D$5:$D$1000,C17)=0,"",MAXIFS(Daily_Entry!$A$5:$A$1000,Daily_Entry!$B$5:$B$1000,"Ante Room",Daily_Entry!$D$5:$D$1000,C17)) | M17: =IF(I17=0,"Not Started",IF(AND(E17<>"",I17>=E17),"Completed","In Progress")) -> Not Started
A18: 12 | B18: Door Work | C18: Air Curtain Installation | D18: Nos | I18: =SUMIFS(Daily_Entry!$F$5:$F$1000,Daily_Entry!$B$5:$B$1000,"Ante Room",Daily_Entry!$D$5:$D$1000,C18) -> 0 | J18: =IF(OR(E18="",E18=0),"",I18/E18) | K18: =IF(E18="","",E18-I18) | L18: =IF(MAXIFS(Daily_Entry!$A$5:$A$1000,Daily_Entry!$B$5:$B$1000,"Ante Room",Daily_Entry!$D$5:$D$1000,C18)=0,"",MAXIFS(Daily_Entry!$A$5:$A$1000,Daily_Entry!$B$5:$B$1000,"Ante Room",Daily_Entry!$D$5:$D$1000,C18)) | M18: =IF(I18=0,"Not Started",IF(AND(E18<>"",I18>=E18),"Completed","In Progress")) -> Not Started
... A21: 15 | B21: Floor & Racking | C21: Floor & Racking Work | D21: Sq.m | I21: =SUMIFS(Daily_Entry!$F$5:$F$1000,Daily_Entry!$B$5:$B$1000,"Ante Room",Daily_Entry!$D$5:$D$1000,C21) -> 0 | J21: =IF(OR(E21="",E21=0),"",I21/E21) | K21: =IF(E21="","",E21-I21) | L21: =IF(MAXIFS(Daily_Entry!$A$5:$A$1000,Daily_Entry!$B$5:$B$1000,"Ante Room",Daily_Entry!$D$5:$D$1000,C21)=0,"",MAXIFS(Daily_Entry!$A$5:$A$1000,Daily_Entry!$B$5:$B$1000,"Ante Room",Daily_Entry!$D$5:$D$1000,C21)) | M21: =IF(I21=0,"Not Started",IF(AND(E21<>"",I21>=E21),"Completed","In Progress")) -> Not Started

Sheet Common_Works
A1: COMMON WORKS (REFRIGERATION & ELECTRICAL) - SCOPE & PROGRESS TRACKER
A4: S.No | B4: Category | C4: Item / Activity | D4: UOM | E4: Target Qty | F4: Planned Start | G4: Planned Finish | H4: Planned Handover | I4: Cumulative Qty Done | J4: % Complete | K4: Balance Qty | L4: Last Updated | M4: Status | N4: Remarks
A5: 1 | B5: Refrigeration | C5: ODU Hanging | D5: Nos | I5: =SUMIFS(Daily_Entry!$F$5:$F$1000,Daily_Entry!$B$5:$B$1000,"Common / Plant-wide",Daily_Entry!$D$5:$D$1000,C5) -> 0 | J5: =IF(OR(E5="",E5=0),"",I5/E5) | K5: =IF(E5="","",E5-I5) | L5: =IF(MAXIFS(Daily_Entry!$A$5:$A$1000,Daily_Entry!$B$5:$B$1000,"Common / Plant-wide",Daily_Entry!$D$5:$D$1000,C5)=0,"",MAXIFS(Daily_Entry!$A$5:$A$1000,Daily_Entry!$B$5:$B$1000,"Common / Plant-wide",Daily_Entry!$D$5:$D$1000,C5)) | M5: =IF(I5=0,"Not Started",IF(AND(E5<>"",I5>=E5),"Completed","In Progress")) -> Not Started
